Workbook

Sheet equipment
A1: Zenless Zone Zero - Drive Disk Overview
A2: last update: | B2: 2025-02-03
A3: data source: | B3: https://www.prydwen.gg/
A4: generator: | B4: https://github.com/Iluntrin/hoyo-equipment-overview
A28: Astral Voice (8)
A29: substats | B29: priority | C29: ATK% | D29: ATK | E29: PEN | F29: CRIT Rate | G29: CRIT DMG | H29: Anomaly Proficiency
A30: combined | C30: =IF(SUM(I31:I38)=0,0,SUM(C31:C38)/SUM(I31:I38)) | D30: =IF(SUM(I31:I38)=0,0,SUM(D31:D38)/SUM(I31:I38)) | E30: =IF(SUM(I31:I38)=0,0,SUM(E31:E38)/SUM(I31:I38)) | F30: =IF(SUM(I31:I38)=0,0,SUM(F31:F38)/SUM(I31:I38)) | G30: =IF(SUM(I31:I38)=0,0,SUM(G31:G38)/SUM(I31:I38)) | H30: =IF(SUM(I31:I38)=0,0,SUM(H31:H38)/SUM(I31:I38))
A31: Astra Yao | B31: 0 | C31: =IF(I31=1,1.0,0) | D31: =IF(I31=1,0.9,0) | E31: =IF(I31=1,0.7,0) | F31: =IF(I31=1,0.8,0) | G31: =IF(I31=1,0.8,0) | H31: =IF(I31=1,0.8,0) | I31: =IF(OR(LOOKUP(A31,characters!A:A,characters!B:B)=-1, LOOKUP(A31,characters!A:A,characters!B:B)+0.1>=B31),1,0)
A32: Lucy | B32: 0 | C32: =IF(I32=1,1.0,0) | D32: =IF(I32=1,0.9,0) | E32: =IF(I32=1,0.9,0) | F32: =IF(I32=1,1.0,0) | G32: =IF(I32=1,1.0,0) | I32: =IF(OR(LOOKUP(A32,characters!A:A,characters!B:B)=-1, LOOKUP(A32,characters!A:A,characters!B:B)+0.1>=B32),1,0)
A33: Nicole | B33: 0 | C33: =IF(I33=1,1.0,0) | D33: =IF(I33=1,0.9,0) | E33: =IF(I33=1,0.9,0) | H33: =IF(I33=1,1.0,0) | I33: =IF(OR(LOOKUP(A33,characters!A:A,characters!B:B)=-1, LOOKUP(A33,characters!A:A,characters!B:B)+0.1>=B33),1,0)
A34: Rina | B34: 0 | C34: =IF(I34=1,0.9,0) | D34: =IF(I34=1,0.8,0) | E34: =IF(I34=1,0.8,0) | H34: =IF(I34=1,1.0,0) | I34: =IF(OR(LOOKUP(A34,characters!A:A,characters!B:B)=-1, LOOKUP(A34,characters!A:A,characters!B:B)+0.1>=B34),1,0)
A35: Seth | B35: 0 | C35: =IF(I35=1,1.0,0) | D35: =IF(I35=1,0.8,0) | E35: =IF(I35=1,0.7,0) | H35: =IF(I35=1,0.9,0) | I35: =IF(OR(LOOKUP(A35,characters!A:A,characters!B:B)=-1, LOOKUP(A35,characters!A:A,characters!B:B)+0.1>=B35),1,0)
A36: Soukaku | B36: 0 | C36: =IF(I36=1,1.0,0) | D36: =IF(I36=1,0.9,0) | E36: =IF(I36=1,0.9,0) | F36: =IF(I36=1,1.0,0) | G36: =IF(I36=1,1.0,0) | I36: =IF(OR(LOOKUP(A36,characters!A:A,characters!B:B)=-1, LOOKUP(A36,characters!A:A,characters!B:B)+0.1>=B36),1,0)
A37: Harumasa | B37: 0.2 | C37: =IF(I37=1,1.0,0) | D37: =IF(I37=1,0.9,0) | E37: =IF(I37=1,0.9,0) | F37: =IF(I37=1,1.0,0) | G37: =IF(I37=1,1.0,0) | I37: =IF(OR(LOOKUP(A37,characters!A:A,characters!B:B)=-1, LOOKUP(A37,characters!A:A,characters!B:B)+0.1>=B37),1,0)
A38: Miyabi | B38: 0.2 | C38: =IF(I38=1,0.99,0) | D38: =IF(I38=1,0.89,0) | E38: =IF(I38=1,0.89,0) | F38: =IF(I38=1,1.0,0) | G38: =IF(I38=1,0.99,0) | H38: =IF(I38=1,0.89,0) | I38: =IF(OR(LOOKUP(A38,characters!A:A,characters!B:B)=-1, LOOKUP(A38,characters!A:A,characters!B:B)+0.1>=B38),1,0)
A40: Disk 4 (main stat) | B40: priority | C40: ATK% | D40: CRIT DMG | E40: CRIT Rate | F40: Anomaly Proficiency
A41: combined | C41: =IF(SUM(G42:G49)=0,0,SUM(C42:C49)/SUM(G42:G49)) | D41: =IF(SUM(G42:G49)=0,0,SUM(D42:D49)/SUM(G42:G49)) | E41: =IF(SUM(G42:G49)=0,0,SUM(E42:E49)/SUM(G42:G49)) | F41: =IF(SUM(G42:G49)=0,0,SUM(F42:F49)/SUM(G42:G49))
A42: Astra Yao | B42: 0 | C42: =IF(G42=1,1.0,0) | G42: =IF(OR(LOOKUP(A42,characters!A:A,characters!B:B)=-1, LOOKUP(A42,characters!A:A,characters!B:B)+0.1>=B42),1,0)
A43: Harumasa | B43: 0.2 | D43: =IF(G43=1,1.0,0) | E43: =IF(G43=1,0.99,0) | G43: =IF(OR(LOOKUP(A43,characters!A:A,characters!B:B)=-1, LOOKUP(A43,characters!A:A,characters!B:B)+0.1>=B43),1,0)
A44: Lucy | B44: 0 | C44: =IF(G44=1,1.0,0) | E44: =IF(G44=1,0.9,0) | G44: =IF(OR(LOOKUP(A44,characters!A:A,characters!B:B)=-1, LOOKUP(A44,characters!A:A,characters!B:B)+0.1>=B44),1,0)
A45: Miyabi | B45: 0.2 | C45: =IF(G45=1,0.99,0) | E45: =IF(G45=1,1.0,0) | G45: =IF(OR(LOOKUP(A45,characters!A:A,characters!B:B)=-1, LOOKUP(A45,characters!A:A,characters!B:B)+0.1>=B45),1,0)
A46: Nicole | B46: 0 | C46: =IF(G46=1,1.0,0) | F46: =IF(G46=1,1.0,0) | G46: =IF(OR(LOOKUP(A46,characters!A:A,characters!B:B)=-1, LOOKUP(A46,characters!A:A,characters!B:B)+0.1>=B46),1,0)
A47: Rina | B47: 0 | C47: =IF(G47=1,1.0,0) | F47: =IF(G47=1,1.0,0) | G47: =IF(OR(LOOKUP(A47,characters!A:A,characters!B:B)=-1, LOOKUP(A47,characters!A:A,characters!B:B)+0.1>=B47),1,0)
A48: Seth | B48: 0 | C48: =IF(G48=1,1.0,0) | F48: =IF(G48=1,0.99,0) | G48: =IF(OR(LOOKUP(A48,characters!A:A,characters!B:B)=-1, LOOKUP(A48,characters!A:A,characters!B:B)+0.1>=B48),1,0)
A49: Soukaku | B49: 0 | C49: =IF(G49=1,1.0,0) | E49: =IF(G49=1,0.9,0) | G49: =IF(OR(LOOKUP(A49,characters!A:A,characters!B:B)=-1, LOOKUP(A49,characters!A:A,characters!B:B)+0.1>=B49),1,0)
A51: Disk 5 (main stat) | B51: priority | C51: ATK% | D51: Electric DMG% | E51: Ice DMG% | F51: Ether DMG% | G51: PEN Ratio%
A52: combined | C52: =IF(SUM(H53:H60)=0,0,SUM(C53:C60)/SUM(H53:H60)) | D52: =IF(SUM(H53:H60)=0,0,SUM(D53:D60)/SUM(H53:H60)) | E52: =IF(SUM(H53:H60)=0,0,SUM(E53:E60)/SUM(H53:H60)) | F52: =IF(SUM(H53:H60)=0,0,SUM(F53:F60)/SUM(H53:H60)) | G52: =IF(SUM(H53:H60)=0,0,SUM(G53:G60)/SUM(H53:H60))
A53: Astra Yao | B53: 0 | C53: =IF(H53=1,1.0,0) | H53: =IF(OR(LOOKUP(A53,characters!A:A,characters!B:B)=-1, LOOKUP(A53,characters!A:A,characters!B:B)+0.1>=B53),1,0)
A54: Harumasa | B54: 0.2 | C54: =IF(H54=1,0.99,0) | D54: =IF(H54=1,1.0,0) | H54: =IF(OR(LOOKUP(A54,characters!A:A,characters!B:B)=-1, LOOKUP(A54,characters!A:A,characters!B:B)+0.1>=B54),1,0)
A55: Lucy | B55: 0 | C55: =IF(H55=1,1.0,0) | H55: =IF(OR(LOOKUP(A55,characters!A:A,characters!B:B)=-1, LOOKUP(A55,characters!A:A,characters!B:B)+0.1>=B55),1,0)
A56: Miyabi | B56: 0.2 | C56: =IF(H56=1,1.0,0) | E56: =IF(H56=1,1.0,0) | H56: =IF(OR(LOOKUP(A56,characters!A:A,characters!B:B)=-1, LOOKUP(A56,characters!A:A,characters!B:B)+0.1>=B56),1,0)
A57: Nicole | B57: 0 | C57: =IF(H57=1,0.9,0) | F57: =IF(H57=1,1.0,0) | H57: =IF(OR(LOOKUP(A57,characters!A:A,characters!B:B)=-1, LOOKUP(A57,characters!A:A,characters!B:B)+0.1>=B57),1,0)
A58: Rina | B58: 0 | G58: =IF(H58=1,1.0,0) | H58: =IF(OR(LOOKUP(A58,characters!A:A,characters!B:B)=-1, LOOKUP(A58,characters!A:A,characters!B:B)+0.1>=B58),1,0)
A59: Seth | B59: 0 | C59: =IF(H59=1,1.0,0) | D59: =IF(H59=1,0.99,0) | H59: =IF(OR(LOOKUP(A59,characters!A:A,characters!B:B)=-1, LOOKUP(A59,characters!A:A,characters!B:B)+0.1>=B59),1,0)
A60: Soukaku | B60: 0 | C60: =IF(H60=1,1.0,0) | E60: =IF(H60=1,0.9,0) | H60: =IF(OR(LOOKUP(A60,characters!A:A,characters!B:B)=-1, LOOKUP(A60,characters!A:A,characters!B:B)+0.1>=B60),1,0)
A62: Disk 6 (main stat) | B62: priority | C62: Energy Regen | D62: ATK% | E62: Anomaly Mastery
A63: combined | C63: =IF(SUM(F64:F71)=0,0,SUM(C64:C71)/SUM(F64:F71)) | D63: =IF(SUM(F64:F71)=0,0,SUM(D64:D71)/SUM(F64:F71)) | E63: =IF(SUM(F64:F71)=0,0,SUM(E64:E71)/SUM(F64:F71))
A64: Astra Yao | B64: 0 | C64: =IF(F64=1,1.0,0) | D64: =IF(F64=1,1.0,0) | F64: =IF(OR(LOOKUP(A64,characters!A:A,characters!B:B)=-1, LOOKUP(A64,characters!A:A,characters!B:B)+0.1>=B64),1,0)
A65: Harumasa | B65: 0.2 | D65: =IF(F65=1,1.0,0) | F65: =IF(OR(LOOKUP(A65,characters!A:A,characters!B:B)=-1, LOOKUP(A65,characters!A:A,characters!B:B)+0.1>=B65),1,0)
A66: Lucy | B66: 0 | C66: =IF(F66=1,1.0,0) | D66: =IF(F66=1,1.0,0) | F66: =IF(OR(LOOKUP(A66,characters!A:A,characters!B:B)=-1, LOOKUP(A66,characters!A:A,characters!B:B)+0.1>=B66),1,0)
...

Sheet characters
A1: Anby | B1: -1 | E1: Explanation:
A2: Anby: Silver Soldier | B2: -1 | E2: -1 show all
A3: Anton | B3: -1 | E3: -2 do not show anything for character
A4: Astra Yao | B4: -1 | E4: 0 show only priority 0 for character (=show only recommended sets)
A5: Ben | B5: -1 | E5: <n> show only priority 0 to <n> for character
A6: Billy | B6: -1
A7: Burnice | B7: -1
A8: Caesar | B8: -1
A9: Corin | B9: -1
A10: Ellen | B10: -1
A11: Evelyn | B11: -1
A12: Grace | B12: -1
A13: Harumasa | B13: -1
A14: Jane Doe | B14: -1
A15: Koleda | B15: -1
A16: Lighter | B16: -1
A17: Lucy | B17: -1
... A31: Zhu Yuan | B31: -1
